<?xml version="1.0" ?>
<!-- =================================================================================== -->
<!-- |    This document was autogenerated by xacro from invpend.urdf.xacro             | -->
<!-- |    EDITING THIS FILE BY HAND IS NOT RECOMMENDED                                 | -->
<!-- =================================================================================== -->
<!-- Revolute-Revolute Manipulator -->
<robot name="invpend">
  <!-- pole radius -->
  <!-- Slider Link -->
  <gazebo reference="slidebar">
    <material>Gazebo/Black</material>
  </gazebo>
  <!-- Cart Link -->
  <gazebo reference="cart">
    <material>Gazebo/Blue</material>
  </gazebo>
  <!-- Pole Link -->
  <gazebo reference="pole">
    <material>Gazebo/Orange</material>
  </gazebo>
  <gazebo>
    <plugin filename="libgazebo_ros2_control.so" name="gazebo_ros2_control">
      <robot_param>robot_description</robot_param>
      <robot_param_node>robot_state_publisher</robot_param_node>
      <parameters>/home/abhilash-ts434/cart/install/cart_description/share/cart_description/config/my_controllers.yaml</parameters>
    </plugin>
  </gazebo>
  <material name="black">
    <color rgba="0.0 0.0 0.0 1.0"/>
  </material>
  <material name="blue">
    <color rgba="0.0 0.0 0.8 1.0"/>
  </material>
  <material name="green">
    <color rgba="0.0 0.8 0.0 1.0"/>
  </material>
  <material name="grey">
    <color rgba="0.2 0.2 0.2 1.0"/>
  </material>
  <material name="orange">
    <color rgba="1.0 0.4235294117647059 0.0392156862745098 1.0"/>
  </material>
  <material name="brown">
    <color rgba="0.8705882352941177 0.8117647058823529 0.7647058823529411 1.0"/>
  </material>
  <material name="red">
    <color rgba="0.8 0.0 0.0 1.0"/>
  </material>
  <material name="white">
    <color rgba="1.0 1.0 1.0 1.0"/>
  </material>
  <!-- <xacro:include filename="ros2_control.xacro"/> -->
  <!-- Used for fixing robot to Gazebo 'base_link' -->
  <link name="world"/>
  <joint name="fixed" type="fixed">
    <parent link="world"/>
    <child link="slidebar"/>
    <origin xyz="0 0 1"/>
  </joint>
  <state_interface name="effort"/>
  <!-- Slider Link -->
  <link name="slidebar">
    <visual>
      <origin rpy="0 0 0" xyz="0 0 0"/>
      <geometry>
        <box size="5 0.01 0.01"/>
      </geometry>
      <material name="black"/>
    </visual>
    <inertial>
      <origin rpy="0 0 0" xyz="0 0 0"/>
      <mass value="100"/>
      <inertia ixx="208.33333333333334" ixy="0.0" ixz="0.0" iyy="0.0" iyz="0.0" izz="208.33333333333334"/>
    </inertial>
  </link>
  <joint name="slider_to_cart" type="prismatic">
    <parent link="slidebar"/>
    <child link="cart"/>
    <origin rpy="0 0 0" xyz="0 0 0"/>
    <axis xyz="1 0 0"/>
    <limit effort="100.0" lower="-2.5" upper="2.5" velocity="100"/>
    <!--dynamics damping="0.0001"/-->
  </joint>
  <!-- Cart Link -->
  <link name="cart">
    <collision>
      <origin rpy="0 0 0" xyz="0 0 0"/>
      <geometry>
        <box size="0.25 0.25 0.125"/>
      </geometry>
    </collision>
    <visual>
      <origin rpy="0 0 0" xyz="0 0 0"/>
      <geometry>
        <box size="0.25 0.25 0.125"/>
      </geometry>
      <material name="blue"/>
    </visual>
    <inertial>
      <origin rpy="0 0 0" xyz="0 0 0"/>
      <mass value="0.5"/>
      <inertia ixx="0.0032552083333333335" ixy="0.0" ixz="0.0" iyy="0.005208333333333333" iyz="0.0" izz="0.0032552083333333335"/>
    </inertial>
  </link>
  <joint name="cart_to_pole" type="revolute">
    <parent link="cart"/>
    <child link="pole"/>
    <origin rpy="0 0 0" xyz="0 -0.14750000000000002 0.03125"/>
    <axis xyz="0 1 0"/>
    <limit effort="100.0" lower="-1.5707963267948966" upper="1.5707963267948966" velocity="100.0"/>
  </joint>
  <!-- Pole Link -->
  <link name="pole">
    <collision>
      <origin rpy="0 0 0" xyz="0 0 0.25"/>
      <geometry>
        <box size="0.025 0.025 0.5"/>
      </geometry>
    </collision>
    <visual>
      <origin rpy="0 0 0" xyz="0 0 0.25"/>
      <geometry>
        <box size="0.025 0.025 0.5"/>
      </geometry>
      <material name="orange"/>
    </visual>
    <inertial>
      <origin rpy="0 0 0" xyz="0 0 0.25"/>
      <mass value="0.2"/>
      <inertia ixx="0.016666666666666666" ixy="0.0" ixz="0.0" iyy="0.0" iyz="0.0" izz="0.016666666666666666"/>
    </inertial>
  </link>
  <!-- Transmission for ros2_control
  <transmission name="transmission_slider">
    <type>transmission_interface/SimpleTransmission</type>
    <joint name="slider_to_cart">
      <hardwareInterface>hardware_interface/VelocityJointInterface</hardwareInterface>
    </joint>
    <actuator name="slider_motor">
      <hardwareInterface>hardware_interface/VelocityJointInterface</hardwareInterface>
      <mechanicalReduction>1</mechanicalReduction>
    </actuator>
  </transmission> -->
</robot>
