<?xml version="1.0" ?>
<!-- =================================================================================== -->
<!-- |    This document was autogenerated by xacro from my_robot.urdf.xacro            | -->
<!-- |    EDITING THIS FILE BY HAND IS NOT RECOMMENDED                                 | -->
<!-- =================================================================================== -->
<robot name="my_robot">
  <material name="green">
    <color rgba="0 0.5 0 1"/>
  </material>
  <material name="grey">
    <color rgba="0.5 0.5 0.5 1"/>
  </material>
  <link name="base_link">
    <visual>
      <geometry>
        <box size="0.6 0.4  0.2"/>
      </geometry>
      <origin rpy="0 0 0" xyz="0 0 0.1"/>
      <material name="green"/>
    </visual>
    <collision>
      <geometry>
        <box size="0.6 0.4  0.2"/>
      </geometry>
      <origin rpy="0 0 0" xyz="0 0 0.1"/>
    </collision>
    <inertial>
      <origin rpy="0 0 0" xyz="0 0 0.1"/>
      <mass value="5.0"/>
      <inertia ixx="0.16666666666666669" ixy="0" ixz="0" iyy="0.21666666666666667" iyz="0" izz="0.08333333333333336"/>
    </inertial>
  </link>
  <link name="rear_right_wheel_link">
    <visual>
      <geometry>
        <cylinder length="0.05" radius="0.1"/>
      </geometry>
      <origin rpy="1.5707963267948966 0 0" xyz="0 0 0"/>
      <material name="grey"/>
    </visual>
    <collision>
      <geometry>
        <cylinder length="0.05" radius="0.1"/>
      </geometry>
      <origin rpy="1.5707963267948966 0 0" xyz="0 0 0"/>
    </collision>
    <inertial>
      <origin rpy="1.5707963267948966 0 0" xyz="0 0 0"/>
      <mass value="1.0"/>
      <inertia ixx="0.002708333333333334" ixy="0" ixz="0" iyy="0.002708333333333334" iyz="0" izz="0.005000000000000001"/>
    </inertial>
  </link>
  <link name="rear_left_wheel_link">
    <visual>
      <geometry>
        <cylinder length="0.05" radius="0.1"/>
      </geometry>
      <origin rpy="1.5707963267948966 0 0" xyz="0 0 0"/>
      <material name="grey"/>
    </visual>
    <collision>
      <geometry>
        <cylinder length="0.05" radius="0.1"/>
      </geometry>
      <origin rpy="1.5707963267948966 0 0" xyz="0 0 0"/>
    </collision>
    <inertial>
      <origin rpy="1.5707963267948966 0 0" xyz="0 0 0"/>
      <mass value="1.0"/>
      <inertia ixx="0.002708333333333334" ixy="0" ixz="0" iyy="0.002708333333333334" iyz="0" izz="0.005000000000000001"/>
    </inertial>
  </link>
  <link name="front_left_wheel_link">
    <visual>
      <geometry>
        <cylinder length="0.05" radius="0.1"/>
      </geometry>
      <origin rpy="1.5707963267948966 0 0" xyz="0 0 0"/>
      <material name="grey"/>
    </visual>
    <collision>
      <geometry>
        <cylinder length="0.05" radius="0.1"/>
      </geometry>
      <origin rpy="1.5707963267948966 0 0" xyz="0 0 0"/>
    </collision>
    <inertial>
      <origin rpy="1.5707963267948966 0 0" xyz="0 0 0"/>
      <mass value="1.0"/>
      <inertia ixx="0.002708333333333334" ixy="0" ixz="0" iyy="0.002708333333333334" iyz="0" izz="0.005000000000000001"/>
    </inertial>
  </link>
  <link name="front_right_wheel_link">
    <visual>
      <geometry>
        <cylinder length="0.05" radius="0.1"/>
      </geometry>
      <origin rpy="1.5707963267948966 0 0" xyz="0 0 0"/>
      <material name="grey"/>
    </visual>
    <collision>
      <geometry>
        <cylinder length="0.05" radius="0.1"/>
      </geometry>
      <origin rpy="1.5707963267948966 0 0" xyz="0 0 0"/>
    </collision>
    <inertial>
      <origin rpy="1.5707963267948966 0 0" xyz="0 0 0"/>
      <mass value="1.0"/>
      <inertia ixx="0.002708333333333334" ixy="0" ixz="0" iyy="0.002708333333333334" iyz="0" izz="0.005000000000000001"/>
    </inertial>
  </link>
  <link name="base_footprint"/>
  <joint name="base_front_right_wheel_joint" type="continuous">
    <parent link="base_link"/>
    <child link="front_right_wheel_link"/>
    <origin rpy="0 0 0" xyz="0.15 -0.225 0"/>
    <axis xyz="0 1 0"/>
  </joint>
  <joint name="base_front_left_wheel_joint" type="continuous">
    <parent link="base_link"/>
    <child link="front_left_wheel_link"/>
    <origin rpy="0 0 0" xyz="0.15 0.225 0"/>
    <axis xyz="0 1 0"/>
  </joint>
  <joint name="base_rear_right_wheel_joint" type="continuous">
    <parent link="base_link"/>
    <child link="rear_right_wheel_link"/>
    <origin rpy="0 0 0" xyz="-0.15 -0.225 0"/>
    <axis xyz="0 1 0"/>
  </joint>
  <joint name="base_rear_left_wheel_joint" type="continuous">
    <parent link="base_link"/>
    <child link="rear_left_wheel_link"/>
    <origin rpy="0 0 0" xyz="-0.15  0.225 0"/>
    <axis xyz="0 1 0"/>
  </joint>
  <joint name="base_joint" type="fixed">
    <parent link="base_footprint"/>
    <child link="base_link"/>
    <origin rpy="0 0 0" xyz="0 0 0.1"/>
  </joint>
  <gazebo reference="base_link">
    <material>
        Gazebo/White
        </material>
  </gazebo>
  <gazebo reference="rear_right_wheel_link">
    <material>
        Gazebo/Green
        </material>
  </gazebo>
  <gazebo reference="rear_left_wheel_link">
    <material>
        Gazebo/Green
        </material>
  </gazebo>
  <gazebo reference="front_right_wheel_link">
    <material>
        Gazebo/Green
        </material>
  </gazebo>
  <gazebo reference="front_left_wheel_link">
    <material>
        Gazebo/Green
        </material>
  </gazebo>
  <gazebo>
    <plugin filename="libgazebo_ros_diff_drive.so" name="diff_drive_control">
      <!-- Update rate in Hz -->
      <update_rate>50</update_rate>
      <!-- wheels -->
      <num_wheel_pairs>2</num_wheel_pairs>
      <left_joint>base_rear_left_wheel_joint</left_joint>
      <right_joint>base_rear_right_wheel_joint</right_joint>
      <left_joint>base_front_left_wheel_joint</left_joint>
      <right_joint>base_front_right_wheel_joint</right_joint>
      <!-- kinematics -->
      <wheel_separation>0.45</wheel_separation>
      <!-- Diameter of the wheels, in meters, defaults to 0.15 m -->
      <wheelDiameter>0.20</wheelDiameter>
      <!-- output -->
      <publish_odom>true</publish_odom>
      <publish_odom_tf>true</publish_odom_tf>
      <publish_wheel_tf>true</publish_wheel_tf>
      <odometry_topic>odom</odometry_topic>
      <odometry_frame>odom</odometry_frame>
      <robot_base_frame>base_footprint</robot_base_frame>
    </plugin>
  </gazebo>
  <!-- <xacro:include filename="camera.xacro"/> -->
</robot>
